W0713 16:12:11.281000 1461138 site-packages/torch/distributed/run.py:766] 
W0713 16:12:11.281000 1461138 site-packages/torch/distributed/run.py:766] *****************************************
W0713 16:12:11.281000 1461138 site-packages/torch/distributed/run.py:766] Setting OMP_NUM_THREADS environment variable for each process to be 1 in default, to avoid your system being overloaded, please further tune the variable for optimal performance in your application as needed. 
W0713 16:12:11.281000 1461138 site-packages/torch/distributed/run.py:766] *****************************************
[W713 16:12:11.211518078 socket.cpp:755] [c10d] The client socket cannot be initialized to connect to [clara10.sc.uni-leipzig.de]:43979 (errno: 97 - Address family not supported by protocol).
[W713 16:12:11.542176792 socket.cpp:755] [c10d] The client socket cannot be initialized to connect to [clara10.sc.uni-leipzig.de]:44011 (errno: 97 - Address family not supported by protocol).
/home/sc.uni-leipzig.de/ci72buri/.conda/envs/cell-vae/bin/python3.10: can't open file '/home/sc.uni-leipzig.de/ci72buri/projects/vae/Leipzig_big_data_praktikum_gene_expression_autoencoder/train.py': [Errno 2] No such file or directory
/home/sc.uni-leipzig.de/ci72buri/.conda/envs/cell-vae/bin/python3.10: can't open file '/home/sc.uni-leipzig.de/ci72buri/projects/vae/Leipzig_big_data_praktikum_gene_expression_autoencoder/train.py': [Errno 2] No such file or directory
/home/sc.uni-leipzig.de/ci72buri/.conda/envs/cell-vae/bin/python3.10: can't open file '/home/sc.uni-leipzig.de/ci72buri/projects/vae/Leipzig_big_data_praktikum_gene_expression_autoencoder/train.py': [Errno 2] No such file or directory
/home/sc.uni-leipzig.de/ci72buri/.conda/envs/cell-vae/bin/python3.10: can't open file '/home/sc.uni-leipzig.de/ci72buri/projects/vae/Leipzig_big_data_praktikum_gene_expression_autoencoder/train.py': [Errno 2] No such file or directory
E0713 16:12:11.761000 1461138 site-packages/torch/distributed/elastic/multiprocessing/api.py:874] failed (exitcode: 2) local_rank: 0 (pid: 1461161) of binary: /home/sc.uni-leipzig.de/ci72buri/.conda/envs/cell-vae/bin/python3.10
Traceback (most recent call last):
  File "/home/sc.uni-leipzig.de/ci72buri/.conda/envs/cell-vae/bin/torchrun", line 8, in <module>
    sys.exit(main())
  File "/home/sc.uni-leipzig.de/ci72buri/.conda/envs/cell-vae/lib/python3.10/site-packages/torch/distributed/elastic/multiprocessing/errors/__init__.py", line 355, in wrapper
    return f(*args, **kwargs)
  File "/home/sc.uni-leipzig.de/ci72buri/.conda/envs/cell-vae/lib/python3.10/site-packages/torch/distributed/run.py", line 892, in main
    run(args)
  File "/home/sc.uni-leipzig.de/ci72buri/.conda/envs/cell-vae/lib/python3.10/site-packages/torch/distributed/run.py", line 883, in run
    elastic_launch(
  File "/home/sc.uni-leipzig.de/ci72buri/.conda/envs/cell-vae/lib/python3.10/site-packages/torch/distributed/launcher/api.py", line 139, in __call__
    return launch_agent(self._config, self._entrypoint, list(args))
  File "/home/sc.uni-leipzig.de/ci72buri/.conda/envs/cell-vae/lib/python3.10/site-packages/torch/distributed/launcher/api.py", line 270, in launch_agent
    raise ChildFailedError(
torch.distributed.elastic.multiprocessing.errors.ChildFailedError: 
============================================================
train.py FAILED
------------------------------------------------------------
Failures:
[1]:
  time      : 2025-07-13_16:12:11
  host      : clara10.sc.uni-leipzig.de
  rank      : 1 (local_rank: 1)
  exitcode  : 2 (pid: 1461162)
  error_file: <N/A>
  traceback : To enable traceback see: https://pytorch.org/docs/stable/elastic/errors.html
[2]:
  time      : 2025-07-13_16:12:11
  host      : clara10.sc.uni-leipzig.de
  rank      : 2 (local_rank: 2)
  exitcode  : 2 (pid: 1461163)
  error_file: <N/A>
  traceback : To enable traceback see: https://pytorch.org/docs/stable/elastic/errors.html
[3]:
  time      : 2025-07-13_16:12:11
  host      : clara10.sc.uni-leipzig.de
  rank      : 3 (local_rank: 3)
  exitcode  : 2 (pid: 1461164)
  error_file: <N/A>
  traceback : To enable traceback see: https://pytorch.org/docs/stable/elastic/errors.html
------------------------------------------------------------
Root Cause (first observed failure):
[0]:
  time      : 2025-07-13_16:12:11
  host      : clara10.sc.uni-leipzig.de
  rank      : 0 (local_rank: 0)
  exitcode  : 2 (pid: 1461161)
  error_file: <N/A>
  traceback : To enable traceback see: https://pytorch.org/docs/stable/elastic/errors.html
============================================================
