[W714 02:10:48.377059759 socket.cpp:755] [c10d] The client socket cannot be initialized to connect to [paula12.sc.uni-leipzig.de]:25633 (errno: 97 - Address family not supported by protocol).
[W714 02:10:48.521902615 socket.cpp:755] [c10d] The client socket cannot be initialized to connect to [paula12.sc.uni-leipzig.de]:42295 (errno: 97 - Address family not supported by protocol).
[default0]:usage: train_vae.py [-h] [--config CONFIG] [--resume RESUME]
[default0]:train_vae.py: error: unrecognized arguments: --log_dir=logs --checkpoint_dir=checkpoints --job_id=14904994
[default1]:usage: train_vae.py [-h] [--config CONFIG] [--resume RESUME]
[default1]:train_vae.py: error: unrecognized arguments: --log_dir=logs --checkpoint_dir=checkpoints --job_id=14904994
[default3]:usage: train_vae.py [-h] [--config CONFIG] [--resume RESUME]
[default3]:train_vae.py: error: unrecognized arguments: --log_dir=logs --checkpoint_dir=checkpoints --job_id=14904994
[default2]:usage: train_vae.py [-h] [--config CONFIG] [--resume RESUME]
[default2]:train_vae.py: error: unrecognized arguments: --log_dir=logs --checkpoint_dir=checkpoints --job_id=14904994
[default5]:usage: train_vae.py [-h] [--config CONFIG] [--resume RESUME]
[default5]:train_vae.py: error: unrecognized arguments: --log_dir=logs --checkpoint_dir=checkpoints --job_id=14904994
[default4]:usage: train_vae.py [-h] [--config CONFIG] [--resume RESUME]
[default4]:train_vae.py: error: unrecognized arguments: --log_dir=logs --checkpoint_dir=checkpoints --job_id=14904994
[default7]:usage: train_vae.py [-h] [--config CONFIG] [--resume RESUME]
[default7]:train_vae.py: error: unrecognized arguments: --log_dir=logs --checkpoint_dir=checkpoints --job_id=14904994
[default6]:usage: train_vae.py [-h] [--config CONFIG] [--resume RESUME]
[default6]:train_vae.py: error: unrecognized arguments: --log_dir=logs --checkpoint_dir=checkpoints --job_id=14904994
W0714 02:10:54.238000 4014216 site-packages/torch/distributed/elastic/multiprocessing/api.py:900] Sending process 4014229 closing signal SIGTERM
W0714 02:10:54.238000 4014216 site-packages/torch/distributed/elastic/multiprocessing/api.py:900] Sending process 4014231 closing signal SIGTERM
W0714 02:10:54.239000 4014216 site-packages/torch/distributed/elastic/multiprocessing/api.py:900] Sending process 4014234 closing signal SIGTERM
W0714 02:10:54.240000 4014216 site-packages/torch/distributed/elastic/multiprocessing/api.py:900] Sending process 4014235 closing signal SIGTERM
W0714 02:10:54.240000 4014216 site-packages/torch/distributed/elastic/multiprocessing/api.py:900] Sending process 4014236 closing signal SIGTERM
E0714 02:10:54.433000 4014216 site-packages/torch/distributed/elastic/multiprocessing/api.py:874] failed (exitcode: 2) local_rank: 1 (pid: 4014230) of binary: /home/sc.uni-leipzig.de/ci72buri/.conda/envs/cell-vae/bin/python3.10
[default0]:usage: train_vae.py [-h] [--config CONFIG] [--resume RESUME]
[default0]:train_vae.py: error: unrecognized arguments: --log_dir=logs --checkpoint_dir=checkpoints --job_id=14904994
[default2]:usage: train_vae.py [-h] [--config CONFIG] [--resume RESUME]
[default2]:train_vae.py: error: unrecognized arguments: --log_dir=logs --checkpoint_dir=checkpoints --job_id=14904994
[default1]:usage: train_vae.py [-h] [--config CONFIG] [--resume RESUME]
[default1]:train_vae.py: error: unrecognized arguments: --log_dir=logs --checkpoint_dir=checkpoints --job_id=14904994
[default3]:usage: train_vae.py [-h] [--config CONFIG] [--resume RESUME]
[default3]:train_vae.py: error: unrecognized arguments: --log_dir=logs --checkpoint_dir=checkpoints --job_id=14904994
[default6]:usage: train_vae.py [-h] [--config CONFIG] [--resume RESUME]
[default6]:train_vae.py: error: unrecognized arguments: --log_dir=logs --checkpoint_dir=checkpoints --job_id=14904994
[default7]:usage: train_vae.py [-h] [--config CONFIG] [--resume RESUME]
[default7]:train_vae.py: error: unrecognized arguments: --log_dir=logs --checkpoint_dir=checkpoints --job_id=14904994
[default4]:usage: train_vae.py [-h] [--config CONFIG] [--resume RESUME]
[default4]:train_vae.py: error: unrecognized arguments: --log_dir=logs --checkpoint_dir=checkpoints --job_id=14904994
[default5]:usage: train_vae.py [-h] [--config CONFIG] [--resume RESUME]
[default5]:train_vae.py: error: unrecognized arguments: --log_dir=logs --checkpoint_dir=checkpoints --job_id=14904994
W0714 02:10:58.772000 4014216 site-packages/torch/distributed/elastic/multiprocessing/api.py:900] Sending process 4014360 closing signal SIGTERM
W0714 02:10:58.773000 4014216 site-packages/torch/distributed/elastic/multiprocessing/api.py:900] Sending process 4014362 closing signal SIGTERM
W0714 02:10:58.773000 4014216 site-packages/torch/distributed/elastic/multiprocessing/api.py:900] Sending process 4014364 closing signal SIGTERM
E0714 02:10:58.968000 4014216 site-packages/torch/distributed/elastic/multiprocessing/api.py:874] failed (exitcode: 2) local_rank: 0 (pid: 4014357) of binary: /home/sc.uni-leipzig.de/ci72buri/.conda/envs/cell-vae/bin/python3.10
[default1]:usage: train_vae.py [-h] [--config CONFIG] [--resume RESUME]
[default1]:train_vae.py: error: unrecognized arguments: --log_dir=logs --checkpoint_dir=checkpoints --job_id=14904994
[default0]:usage: train_vae.py [-h] [--config CONFIG] [--resume RESUME]
[default0]:train_vae.py: error: unrecognized arguments: --log_dir=logs --checkpoint_dir=checkpoints --job_id=14904994
[default5]:usage: train_vae.py [-h] [--config CONFIG] [--resume RESUME]
[default5]:train_vae.py: error: unrecognized arguments: --log_dir=logs --checkpoint_dir=checkpoints --job_id=14904994
[default6]:usage: train_vae.py [-h] [--config CONFIG] [--resume RESUME]
[default6]:train_vae.py: error: unrecognized arguments: --log_dir=logs --checkpoint_dir=checkpoints --job_id=14904994
[default2]:usage: train_vae.py [-h] [--config CONFIG] [--resume RESUME]
[default2]:train_vae.py: error: unrecognized arguments: --log_dir=logs --checkpoint_dir=checkpoints --job_id=14904994
[default7]:usage: train_vae.py [-h] [--config CONFIG] [--resume RESUME]
[default7]:train_vae.py: error: unrecognized arguments: --log_dir=logs --checkpoint_dir=checkpoints --job_id=14904994
[default3]:usage: train_vae.py [-h] [--config CONFIG] [--resume RESUME]
[default3]:train_vae.py: error: unrecognized arguments: --log_dir=logs --checkpoint_dir=checkpoints --job_id=14904994
[default4]:usage: train_vae.py [-h] [--config CONFIG] [--resume RESUME]
[default4]:train_vae.py: error: unrecognized arguments: --log_dir=logs --checkpoint_dir=checkpoints --job_id=14904994
W0714 02:11:02.906000 4014216 site-packages/torch/distributed/elastic/multiprocessing/api.py:900] Sending process 4014463 closing signal SIGTERM
W0714 02:11:02.907000 4014216 site-packages/torch/distributed/elastic/multiprocessing/api.py:900] Sending process 4014465 closing signal SIGTERM
W0714 02:11:02.907000 4014216 site-packages/torch/distributed/elastic/multiprocessing/api.py:900] Sending process 4014466 closing signal SIGTERM
W0714 02:11:02.908000 4014216 site-packages/torch/distributed/elastic/multiprocessing/api.py:900] Sending process 4014467 closing signal SIGTERM
W0714 02:11:02.908000 4014216 site-packages/torch/distributed/elastic/multiprocessing/api.py:900] Sending process 4014468 closing signal SIGTERM
W0714 02:11:02.909000 4014216 site-packages/torch/distributed/elastic/multiprocessing/api.py:900] Sending process 4014469 closing signal SIGTERM
W0714 02:11:02.909000 4014216 site-packages/torch/distributed/elastic/multiprocessing/api.py:900] Sending process 4014470 closing signal SIGTERM
E0714 02:11:03.004000 4014216 site-packages/torch/distributed/elastic/multiprocessing/api.py:874] failed (exitcode: 2) local_rank: 1 (pid: 4014464) of binary: /home/sc.uni-leipzig.de/ci72buri/.conda/envs/cell-vae/bin/python3.10
[default1]:usage: train_vae.py [-h] [--config CONFIG] [--resume RESUME]
[default1]:train_vae.py: error: unrecognized arguments: --log_dir=logs --checkpoint_dir=checkpoints --job_id=14904994
[default0]:usage: train_vae.py [-h] [--config CONFIG] [--resume RESUME]
[default0]:train_vae.py: error: unrecognized arguments: --log_dir=logs --checkpoint_dir=checkpoints --job_id=14904994
[default2]:usage: train_vae.py [-h] [--config CONFIG] [--resume RESUME]
[default2]:train_vae.py: error: unrecognized arguments: --log_dir=logs --checkpoint_dir=checkpoints --job_id=14904994
[default3]:usage: train_vae.py [-h] [--config CONFIG] [--resume RESUME]
[default3]:train_vae.py: error: unrecognized arguments: --log_dir=logs --checkpoint_dir=checkpoints --job_id=14904994
[default5]:usage: train_vae.py [-h] [--config CONFIG] [--resume RESUME]
[default5]:train_vae.py: error: unrecognized arguments: --log_dir=logs --checkpoint_dir=checkpoints --job_id=14904994
[default4]:usage: train_vae.py [-h] [--config CONFIG] [--resume RESUME]
[default4]:train_vae.py: error: unrecognized arguments: --log_dir=logs --checkpoint_dir=checkpoints --job_id=14904994
[default6]:usage: train_vae.py [-h] [--config CONFIG] [--resume RESUME]
[default6]:train_vae.py: error: unrecognized arguments: --log_dir=logs --checkpoint_dir=checkpoints --job_id=14904994
[default7]:usage: train_vae.py [-h] [--config CONFIG] [--resume RESUME]
[default7]:train_vae.py: error: unrecognized arguments: --log_dir=logs --checkpoint_dir=checkpoints --job_id=14904994
W0714 02:11:07.442000 4014216 site-packages/torch/distributed/elastic/multiprocessing/api.py:900] Sending process 4014580 closing signal SIGTERM
W0714 02:11:07.442000 4014216 site-packages/torch/distributed/elastic/multiprocessing/api.py:900] Sending process 4014582 closing signal SIGTERM
W0714 02:11:07.443000 4014216 site-packages/torch/distributed/elastic/multiprocessing/api.py:900] Sending process 4014585 closing signal SIGTERM
E0714 02:11:07.638000 4014216 site-packages/torch/distributed/elastic/multiprocessing/api.py:874] failed (exitcode: 2) local_rank: 0 (pid: 4014579) of binary: /home/sc.uni-leipzig.de/ci72buri/.conda/envs/cell-vae/bin/python3.10
Traceback (most recent call last):
  File "/home/sc.uni-leipzig.de/ci72buri/.conda/envs/cell-vae/bin/torchrun", line 8, in <module>
    sys.exit(main())
  File "/home/sc.uni-leipzig.de/ci72buri/.conda/envs/cell-vae/lib/python3.10/site-packages/torch/distributed/elastic/multiprocessing/errors/__init__.py", line 355, in wrapper
    return f(*args, **kwargs)
  File "/home/sc.uni-leipzig.de/ci72buri/.conda/envs/cell-vae/lib/python3.10/site-packages/torch/distributed/run.py", line 892, in main
    run(args)
  File "/home/sc.uni-leipzig.de/ci72buri/.conda/envs/cell-vae/lib/python3.10/site-packages/torch/distributed/run.py", line 883, in run
    elastic_launch(
  File "/home/sc.uni-leipzig.de/ci72buri/.conda/envs/cell-vae/lib/python3.10/site-packages/torch/distributed/launcher/api.py", line 139, in __call__
    return launch_agent(self._config, self._entrypoint, list(args))
  File "/home/sc.uni-leipzig.de/ci72buri/.conda/envs/cell-vae/lib/python3.10/site-packages/torch/distributed/launcher/api.py", line 270, in launch_agent
    raise ChildFailedError(
torch.distributed.elastic.multiprocessing.errors.ChildFailedError: 
============================================================
train_vae.py FAILED
------------------------------------------------------------
Failures:
[1]:
  time      : 2025-07-14_02:11:07
  host      : paula12.sc.uni-leipzig.de
  rank      : 2 (local_rank: 2)
  exitcode  : 2 (pid: 4014581)
  error_file: <N/A>
  traceback : To enable traceback see: https://pytorch.org/docs/stable/elastic/errors.html
[2]:
  time      : 2025-07-14_02:11:07
  host      : paula12.sc.uni-leipzig.de
  rank      : 4 (local_rank: 4)
  exitcode  : 2 (pid: 4014583)
  error_file: <N/A>
  traceback : To enable traceback see: https://pytorch.org/docs/stable/elastic/errors.html
[3]:
  time      : 2025-07-14_02:11:07
  host      : paula12.sc.uni-leipzig.de
  rank      : 5 (local_rank: 5)
  exitcode  : 2 (pid: 4014584)
  error_file: <N/A>
  traceback : To enable traceback see: https://pytorch.org/docs/stable/elastic/errors.html
[4]:
  time      : 2025-07-14_02:11:07
  host      : paula12.sc.uni-leipzig.de
  rank      : 7 (local_rank: 7)
  exitcode  : 2 (pid: 4014586)
  error_file: <N/A>
  traceback : To enable traceback see: https://pytorch.org/docs/stable/elastic/errors.html
------------------------------------------------------------
Root Cause (first observed failure):
[0]:
  time      : 2025-07-14_02:11:07
  host      : paula12.sc.uni-leipzig.de
  rank      : 0 (local_rank: 0)
  exitcode  : 2 (pid: 4014579)
  error_file: <N/A>
  traceback : To enable traceback see: https://pytorch.org/docs/stable/elastic/errors.html
============================================================
