/var/spool/slurmd/job14898676/slurm_script: line 13: activate: No such file or directory
W0713 16:17:58.741000 1407158 site-packages/torch/distributed/run.py:766] 
W0713 16:17:58.741000 1407158 site-packages/torch/distributed/run.py:766] *****************************************
W0713 16:17:58.741000 1407158 site-packages/torch/distributed/run.py:766] Setting OMP_NUM_THREADS environment variable for each process to be 1 in default, to avoid your system being overloaded, please further tune the variable for optimal performance in your application as needed. 
W0713 16:17:58.741000 1407158 site-packages/torch/distributed/run.py:766] *****************************************
[W713 16:17:58.300259941 socket.cpp:755] [c10d] The client socket cannot be initialized to connect to [clara09.sc.uni-leipzig.de]:15206 (errno: 97 - Address family not supported by protocol).
[W713 16:17:58.522297160 socket.cpp:755] [c10d] The client socket cannot be initialized to connect to [clara09.sc.uni-leipzig.de]:44419 (errno: 97 - Address family not supported by protocol).
[W713 16:18:06.198681729 socket.cpp:755] [c10d] The client socket cannot be initialized to connect to [clara09.sc.uni-leipzig.de]:44419 (errno: 97 - Address family not supported by protocol).
[W713 16:18:06.198690289 socket.cpp:755] [c10d] The client socket cannot be initialized to connect to [clara09.sc.uni-leipzig.de]:44419 (errno: 97 - Address family not supported by protocol).
[W713 16:18:06.199213598 socket.cpp:755] [c10d] The client socket cannot be initialized to connect to [clara09.sc.uni-leipzig.de]:44419 (errno: 97 - Address family not supported by protocol).
[W713 16:18:06.199221758 socket.cpp:755] [c10d] The client socket cannot be initialized to connect to [clara09.sc.uni-leipzig.de]:44419 (errno: 97 - Address family not supported by protocol).
wandb: Currently logged in as: coyfelix7 (coyfelix7-universit-t-leipzig) to https://api.wandb.ai. Use `wandb login --relogin` to force relogin
wandb: Tracking run with wandb version 0.21.0
wandb: Run data is saved locally in /home/sc.uni-leipzig.de/ci72buri/projects/vae/Leipzig_big_data_praktikum_gene_expression_autoencoder/wandb/run-20250713_161807-5us783jf
wandb: Run `wandb offline` to turn off syncing.
wandb: Syncing run graceful-frost-153
wandb: ‚≠êÔ∏è View project at https://wandb.ai/coyfelix7-universit-t-leipzig/big_data_vae
wandb: üöÄ View run at https://wandb.ai/coyfelix7-universit-t-leipzig/big_data_vae/runs/5us783jf
Using VAE-optimized preprocessing...Using VAE-optimized preprocessing...

Using VAE-optimized preprocessing...
Using VAE-optimized preprocessing...
Dataset loaded: 20000 cells √ó 100 genes
Dataset loaded: 20000 cells √ó 100 genes
Dataset loaded: 20000 cells √ó 100 genes
Dataset loaded: 20000 cells √ó 100 genes
/home/sc.uni-leipzig.de/ci72buri/projects/vae/Leipzig_big_data_praktikum_gene_expression_autoencoder/autoCell/data_loader.py:152: ImplicitModificationWarning: Modifying `X` on a view results in data being overridden
  self.adata.X = X
/home/sc.uni-leipzig.de/ci72buri/projects/vae/Leipzig_big_data_praktikum_gene_expression_autoencoder/autoCell/data_loader.py:152: ImplicitModificationWarning: Modifying `X` on a view results in data being overridden
  self.adata.X = X
/home/sc.uni-leipzig.de/ci72buri/projects/vae/Leipzig_big_data_praktikum_gene_expression_autoencoder/autoCell/data_loader.py:152: ImplicitModificationWarning: Modifying `X` on a view results in data being overridden
  self.adata.X = X
/home/sc.uni-leipzig.de/ci72buri/projects/vae/Leipzig_big_data_praktikum_gene_expression_autoencoder/autoCell/data_loader.py:152: ImplicitModificationWarning: Modifying `X` on a view results in data being overridden
  self.adata.X = X
Dataset loaded: 20000 cells √ó 100 genes
Dataset loaded: 20000 cells √ó 100 genes
[rank3]: Traceback (most recent call last):
[rank3]:   File "/home/sc.uni-leipzig.de/ci72buri/projects/vae/Leipzig_big_data_praktikum_gene_expression_autoencoder/train_vae.py", line 163, in <module>
[rank3]:     train()
[rank3]:   File "/home/sc.uni-leipzig.de/ci72buri/projects/vae/Leipzig_big_data_praktikum_gene_expression_autoencoder/train_vae.py", line 112, in train
[rank3]:     model = CellVAE(input_dim=dataset.n_genes, latent_dim=latent_dim, use_variance=use_variance).to(device)
[rank3]: NameError: name 'CellVAE' is not defined
Dataset loaded: 20000 cells √ó 100 genes
[rank1]: Traceback (most recent call last):
[rank1]:   File "/home/sc.uni-leipzig.de/ci72buri/projects/vae/Leipzig_big_data_praktikum_gene_expression_autoencoder/train_vae.py", line 163, in <module>
[rank1]:     train()
[rank1]:   File "/home/sc.uni-leipzig.de/ci72buri/projects/vae/Leipzig_big_data_praktikum_gene_expression_autoencoder/train_vae.py", line 112, in train
[rank1]:     model = CellVAE(input_dim=dataset.n_genes, latent_dim=latent_dim, use_variance=use_variance).to(device)
[rank1]: NameError: name 'CellVAE' is not defined
Traceback (most recent call last):
  File "/home/sc.uni-leipzig.de/ci72buri/projects/vae/Leipzig_big_data_praktikum_gene_expression_autoencoder/train_vae.py", line 163, in <module>
    train()
  File "/home/sc.uni-leipzig.de/ci72buri/projects/vae/Leipzig_big_data_praktikum_gene_expression_autoencoder/train_vae.py", line 112, in train
    model = CellVAE(input_dim=dataset.n_genes, latent_dim=latent_dim, use_variance=use_variance).to(device)
NameError: name 'CellVAE' is not defined
[rank0]: Traceback (most recent call last):
[rank0]:   File "/home/sc.uni-leipzig.de/ci72buri/projects/vae/Leipzig_big_data_praktikum_gene_expression_autoencoder/train_vae.py", line 163, in <module>
[rank0]:     train()
[rank0]:   File "/home/sc.uni-leipzig.de/ci72buri/projects/vae/Leipzig_big_data_praktikum_gene_expression_autoencoder/train_vae.py", line 112, in train
[rank0]:     model = CellVAE(input_dim=dataset.n_genes, latent_dim=latent_dim, use_variance=use_variance).to(device)
[rank0]: NameError: name 'CellVAE' is not defined
Dataset loaded: 20000 cells √ó 100 genes
[rank2]: Traceback (most recent call last):
[rank2]:   File "/home/sc.uni-leipzig.de/ci72buri/projects/vae/Leipzig_big_data_praktikum_gene_expression_autoencoder/train_vae.py", line 163, in <module>
[rank2]:     train()
[rank2]:   File "/home/sc.uni-leipzig.de/ci72buri/projects/vae/Leipzig_big_data_praktikum_gene_expression_autoencoder/train_vae.py", line 112, in train
[rank2]:     model = CellVAE(input_dim=dataset.n_genes, latent_dim=latent_dim, use_variance=use_variance).to(device)
[rank2]: NameError: name 'CellVAE' is not defined
W0713 16:18:24.193000 1407158 site-packages/torch/distributed/elastic/multiprocessing/api.py:900] Sending process 1407182 closing signal SIGTERM
W0713 16:18:24.194000 1407158 site-packages/torch/distributed/elastic/multiprocessing/api.py:900] Sending process 1407183 closing signal SIGTERM
W0713 16:18:24.194000 1407158 site-packages/torch/distributed/elastic/multiprocessing/api.py:900] Sending process 1407185 closing signal SIGTERM
[1;34mwandb[0m: 
[1;34mwandb[0m: üöÄ View run [33mgraceful-frost-153[0m at: [34mhttps://wandb.ai/coyfelix7-universit-t-leipzig/big_data_vae/runs/5us783jf[0m
[1;34mwandb[0m: Find logs at: [1;35mwandb/run-20250713_161807-5us783jf/logs[0m
E0713 16:18:24.459000 1407158 site-packages/torch/distributed/elastic/multiprocessing/api.py:874] failed (exitcode: 1) local_rank: 2 (pid: 1407184) of binary: /home/sc.uni-leipzig.de/ci72buri/.conda/envs/cell-vae/bin/python3.10
Traceback (most recent call last):
  File "/home/sc.uni-leipzig.de/ci72buri/.conda/envs/cell-vae/bin/torchrun", line 8, in <module>
    sys.exit(main())
  File "/home/sc.uni-leipzig.de/ci72buri/.conda/envs/cell-vae/lib/python3.10/site-packages/torch/distributed/elastic/multiprocessing/errors/__init__.py", line 355, in wrapper
    return f(*args, **kwargs)
  File "/home/sc.uni-leipzig.de/ci72buri/.conda/envs/cell-vae/lib/python3.10/site-packages/torch/distributed/run.py", line 892, in main
    run(args)
  File "/home/sc.uni-leipzig.de/ci72buri/.conda/envs/cell-vae/lib/python3.10/site-packages/torch/distributed/run.py", line 883, in run
    elastic_launch(
  File "/home/sc.uni-leipzig.de/ci72buri/.conda/envs/cell-vae/lib/python3.10/site-packages/torch/distributed/launcher/api.py", line 139, in __call__
    return launch_agent(self._config, self._entrypoint, list(args))
  File "/home/sc.uni-leipzig.de/ci72buri/.conda/envs/cell-vae/lib/python3.10/site-packages/torch/distributed/launcher/api.py", line 270, in launch_agent
    raise ChildFailedError(
torch.distributed.elastic.multiprocessing.errors.ChildFailedError: 
============================================================
train_vae.py FAILED
------------------------------------------------------------
Failures:
  <NO_OTHER_FAILURES>
------------------------------------------------------------
Root Cause (first observed failure):
[0]:
  time      : 2025-07-13_16:18:24
  host      : clara09.sc.uni-leipzig.de
  rank      : 2 (local_rank: 2)
  exitcode  : 1 (pid: 1407184)
  error_file: <N/A>
  traceback : To enable traceback see: https://pytorch.org/docs/stable/elastic/errors.html
============================================================
