MASTER_ADDR is 172.18.62.11
PING 172.18.62.11 (172.18.62.11) 56(84) bytes of data.
64 bytes from 172.18.62.11: icmp_seq=1 ttl=64 time=0.022 ms

--- 172.18.62.11 ping statistics ---
1 packets transmitted, 1 received, 0% packet loss, time 0ms
rtt min/avg/max/mdev = 0.022/0.022/0.022/0.000 ms
W0715 00:25:22.301000 38705 site-packages/torch/distributed/run.py:766] 
W0715 00:25:22.301000 38705 site-packages/torch/distributed/run.py:766] *****************************************
W0715 00:25:22.301000 38705 site-packages/torch/distributed/run.py:766] Setting OMP_NUM_THREADS environment variable for each process to be 1 in default, to avoid your system being overloaded, please further tune the variable for optimal performance in your application as needed. 
W0715 00:25:22.301000 38705 site-packages/torch/distributed/run.py:766] *****************************************
[W715 00:25:22.262189354 socket.cpp:755] [c10d] The client socket cannot be initialized to connect to [paula11.sc.uni-leipzig.de]:24220 (errno: 97 - Address family not supported by protocol).
[W715 00:25:22.574377249 socket.cpp:755] [c10d] The client socket cannot be initialized to connect to [paula11.sc.uni-leipzig.de]:44303 (errno: 97 - Address family not supported by protocol).
[W715 00:25:26.692268262 socket.cpp:755] [c10d] The client socket cannot be initialized to connect to [paula11.sc.uni-leipzig.de]:44303 (errno: 97 - Address family not supported by protocol).
[W715 00:25:26.692296896 socket.cpp:755] [c10d] The client socket cannot be initialized to connect to [paula11.sc.uni-leipzig.de]:44303 (errno: 97 - Address family not supported by protocol).
[W715 00:25:26.692615255 socket.cpp:755] [c10d] The client socket cannot be initialized to connect to [paula11.sc.uni-leipzig.de]:44303 (errno: 97 - Address family not supported by protocol).
[W715 00:25:26.692728919 socket.cpp:755] [c10d] The client socket cannot be initialized to connect to [paula11.sc.uni-leipzig.de]:44303 (errno: 97 - Address family not supported by protocol).
[W715 00:25:26.693133520 socket.cpp:755] [c10d] The client socket cannot be initialized to connect to [paula11.sc.uni-leipzig.de]:44303 (errno: 97 - Address family not supported by protocol).
wandb: Currently logged in as: coyfelix7 (coyfelix7-universit-t-leipzig) to https://api.wandb.ai. Use `wandb login --relogin` to force relogin
Using VAE-optimized preprocessing...
[rank3]: Traceback (most recent call last):
[rank3]:   File "/home/sc.uni-leipzig.de/ci72buri/projects/vae/Leipzig_big_data_praktikum_gene_expression_autoencoder/train_vae.py", line 179, in <module>
[rank3]:     train()
[rank3]:   File "/home/sc.uni-leipzig.de/ci72buri/projects/vae/Leipzig_big_data_praktikum_gene_expression_autoencoder/train_vae.py", line 104, in train
[rank3]:     dataset_tmp = SingleCellDataset(
[rank3]:   File "/home/sc.uni-leipzig.de/ci72buri/projects/vae/Leipzig_big_data_praktikum_gene_expression_autoencoder/autoCell/data_loader.py", line 50, in __init__
[rank3]:     self._load_data()
[rank3]:   File "/home/sc.uni-leipzig.de/ci72buri/projects/vae/Leipzig_big_data_praktikum_gene_expression_autoencoder/autoCell/data_loader.py", line 79, in _load_data
[rank3]:     processed_X, hvg_indices = self.preprocess_for_vae(
[rank3]: TypeError: SingleCellDataset.preprocess_for_vae() got an unexpected keyword argument 'min_mean'
Using VAE-optimized preprocessing...
[rank1]: Traceback (most recent call last):
[rank1]:   File "/home/sc.uni-leipzig.de/ci72buri/projects/vae/Leipzig_big_data_praktikum_gene_expression_autoencoder/train_vae.py", line 179, in <module>
[rank1]:     train()
[rank1]:   File "/home/sc.uni-leipzig.de/ci72buri/projects/vae/Leipzig_big_data_praktikum_gene_expression_autoencoder/train_vae.py", line 104, in train
[rank1]:     dataset_tmp = SingleCellDataset(
[rank1]:   File "/home/sc.uni-leipzig.de/ci72buri/projects/vae/Leipzig_big_data_praktikum_gene_expression_autoencoder/autoCell/data_loader.py", line 50, in __init__
[rank1]:     self._load_data()
[rank1]:   File "/home/sc.uni-leipzig.de/ci72buri/projects/vae/Leipzig_big_data_praktikum_gene_expression_autoencoder/autoCell/data_loader.py", line 79, in _load_data
[rank1]:     processed_X, hvg_indices = self.preprocess_for_vae(
[rank1]: TypeError: SingleCellDataset.preprocess_for_vae() got an unexpected keyword argument 'min_mean'
Using VAE-optimized preprocessing...
Using VAE-optimized preprocessing...
[rank4]: Traceback (most recent call last):
[rank4]:   File "/home/sc.uni-leipzig.de/ci72buri/projects/vae/Leipzig_big_data_praktikum_gene_expression_autoencoder/train_vae.py", line 179, in <module>
[rank4]:     train()
[rank4]:   File "/home/sc.uni-leipzig.de/ci72buri/projects/vae/Leipzig_big_data_praktikum_gene_expression_autoencoder/train_vae.py", line 104, in train
[rank4]:     dataset_tmp = SingleCellDataset(
[rank4]:   File "/home/sc.uni-leipzig.de/ci72buri/projects/vae/Leipzig_big_data_praktikum_gene_expression_autoencoder/autoCell/data_loader.py", line 50, in __init__
[rank4]:     self._load_data()
[rank4]:   File "/home/sc.uni-leipzig.de/ci72buri/projects/vae/Leipzig_big_data_praktikum_gene_expression_autoencoder/autoCell/data_loader.py", line 79, in _load_data
[rank4]:     processed_X, hvg_indices = self.preprocess_for_vae(
[rank4]: TypeError: SingleCellDataset.preprocess_for_vae() got an unexpected keyword argument 'min_mean'
[rank2]: Traceback (most recent call last):
[rank2]:   File "/home/sc.uni-leipzig.de/ci72buri/projects/vae/Leipzig_big_data_praktikum_gene_expression_autoencoder/train_vae.py", line 179, in <module>
[rank2]:     train()
[rank2]:   File "/home/sc.uni-leipzig.de/ci72buri/projects/vae/Leipzig_big_data_praktikum_gene_expression_autoencoder/train_vae.py", line 104, in train
[rank2]:     dataset_tmp = SingleCellDataset(
[rank2]:   File "/home/sc.uni-leipzig.de/ci72buri/projects/vae/Leipzig_big_data_praktikum_gene_expression_autoencoder/autoCell/data_loader.py", line 50, in __init__
[rank2]:     self._load_data()
[rank2]:   File "/home/sc.uni-leipzig.de/ci72buri/projects/vae/Leipzig_big_data_praktikum_gene_expression_autoencoder/autoCell/data_loader.py", line 79, in _load_data
[rank2]:     processed_X, hvg_indices = self.preprocess_for_vae(
[rank2]: TypeError: SingleCellDataset.preprocess_for_vae() got an unexpected keyword argument 'min_mean'
wandb: Tracking run with wandb version 0.21.0
wandb: Run data is saved locally in /home/sc.uni-leipzig.de/ci72buri/projects/vae/Leipzig_big_data_praktikum_gene_expression_autoencoder/wandb/run-20250715_002528-cfekldjl
wandb: Run `wandb offline` to turn off syncing.
wandb: Syncing run chocolate-snow-199
wandb: ‚≠êÔ∏è View project at https://wandb.ai/coyfelix7-universit-t-leipzig/big_data_vae
wandb: üöÄ View run at https://wandb.ai/coyfelix7-universit-t-leipzig/big_data_vae/runs/cfekldjl
W0715 00:25:29.343000 38705 site-packages/torch/distributed/elastic/multiprocessing/api.py:900] Sending process 38732 closing signal SIGTERM
W0715 00:25:29.343000 38705 site-packages/torch/distributed/elastic/multiprocessing/api.py:900] Sending process 38733 closing signal SIGTERM
W0715 00:25:29.344000 38705 site-packages/torch/distributed/elastic/multiprocessing/api.py:900] Sending process 38735 closing signal SIGTERM
W0715 00:25:29.344000 38705 site-packages/torch/distributed/elastic/multiprocessing/api.py:900] Sending process 38736 closing signal SIGTERM
E0715 00:25:29.985000 38705 site-packages/torch/distributed/elastic/multiprocessing/api.py:874] failed (exitcode: 1) local_rank: 2 (pid: 38734) of binary: /home/sc.uni-leipzig.de/ci72buri/.conda/envs/cell-vae/bin/python3.10
Traceback (most recent call last):
  File "/home/sc.uni-leipzig.de/ci72buri/.conda/envs/cell-vae/bin/torchrun", line 8, in <module>
    sys.exit(main())
  File "/home/sc.uni-leipzig.de/ci72buri/.conda/envs/cell-vae/lib/python3.10/site-packages/torch/distributed/elastic/multiprocessing/errors/__init__.py", line 355, in wrapper
    return f(*args, **kwargs)
  File "/home/sc.uni-leipzig.de/ci72buri/.conda/envs/cell-vae/lib/python3.10/site-packages/torch/distributed/run.py", line 892, in main
    run(args)
  File "/home/sc.uni-leipzig.de/ci72buri/.conda/envs/cell-vae/lib/python3.10/site-packages/torch/distributed/run.py", line 883, in run
    elastic_launch(
  File "/home/sc.uni-leipzig.de/ci72buri/.conda/envs/cell-vae/lib/python3.10/site-packages/torch/distributed/launcher/api.py", line 139, in __call__
    return launch_agent(self._config, self._entrypoint, list(args))
  File "/home/sc.uni-leipzig.de/ci72buri/.conda/envs/cell-vae/lib/python3.10/site-packages/torch/distributed/launcher/api.py", line 270, in launch_agent
    raise ChildFailedError(
torch.distributed.elastic.multiprocessing.errors.ChildFailedError: 
============================================================
train_vae.py FAILED
------------------------------------------------------------
Failures:
  <NO_OTHER_FAILURES>
------------------------------------------------------------
Root Cause (first observed failure):
[0]:
  time      : 2025-07-15_00:25:29
  host      : paula11.sc.uni-leipzig.de
  rank      : 2 (local_rank: 2)
  exitcode  : 1 (pid: 38734)
  error_file: <N/A>
  traceback : To enable traceback see: https://pytorch.org/docs/stable/elastic/errors.html
============================================================
